<?xml version="1.0" encoding="utf-8"?>
<!-- This URDF was automatically created by SolidWorks to URDF Exporter! Originally created by Stephen Brawner (brawner@gmail.com) 
     Commit Version: 1.6.0-4-g7f85cfe  Build Version: 1.6.7995.38578
     For more information, please see http://wiki.ros.org/sw_urdf_exporter -->
<robot
  name="zwzArm">
  <link name="world" />
    <joint name="base_to_world" type="fixed">
              <parent link="world" />
              <child link="base_link" />
              <origin xyz="0 0 0" rpy="0 0 0" />
    </joint>
  <link
    name="base_link">
    <inertial>
      <origin
        xyz="0 0 0.25"
        rpy="0 0 0" />
      <mass
        value="2.89269908169872" />
      <inertia
        ixx="0.0816417751742525"
        ixy="2.35098870164458E-36"
        ixz="-7.15148590763729E-21"
        iyy="0.083367899791627"
        iyz="0"
        izz="0.0029314159014156" />
    </inertial>
    <visual>
      <origin
        xyz="0 0 0"
        rpy="0 0 0" />
      <geometry>
        <mesh
          filename="src/arm_dynamics_hw/urdf/zwzArm/meshes/base_link.STL" />
      </geometry>
      <material
        name="">
        <color
          rgba="1 1 1 1" />
      </material>
    </visual>
    <!-- <collision>
      <origin
        xyz="0 0 0"
        rpy="0 0 0" />
      <geometry>
        <mesh
          filename="package://zwzArm/meshes/base_link.STL" />
      </geometry>
    </collision> -->
  </link>
    <joint
      name="joint1"
      type="continuous">
      <origin
        xyz="0 0 0.5"
        rpy="0 0 0" />
      <parent
        link="base_link" />
      <child
        link="link1" />
      <axis
        xyz="0 -1 0" />
      <limit
        effort="200"
        velocity="30" />
    </joint>
  <link
    name="link1">
    <inertial>
      <origin
        xyz="0.16 6.66941865451896E-16 1.11022302462516E-16"
        rpy="0 0 0" />
      <mass
        value="2.09269908169872" />
      <inertia
        ixx="0.00458895642020568"
        ixy="-4.2351647362715E-18"
        ixz="3.90142893814097E-18"
        iyy="0.0282839703436107"
        iyz="2.25382207098483E-19"
        izz="0.0295487195783597" />
    </inertial>
    <visual>
      <origin
        xyz="0 0 0"
        rpy="0 0 0" />
      <geometry>
        <mesh
          filename="src/arm_dynamics_hw/urdf/zwzArm/meshes/link1.STL" />
      </geometry>
      <material
        name="">
        <color
          rgba="1 1 1 1" />
      </material>
    </visual>
    <!-- <collision>
      <origin
        xyz="0 0 0"
        rpy="0 0 0" />
      <geometry>
        <mesh
          filename="package://zwzArm/meshes/link1.STL" />
      </geometry>
    </collision> -->
  </link>
     <joint
    name="joint2"
    type="continuous">
    <origin
      xyz="0.32 0 0"
      rpy="0 0 0" />
    <parent
      link="link1" />
    <child
      link="link2" />
    <axis
      xyz="0 -1 0" />
    <limit
      effort="200"
      velocity="30" />
  </joint>
  
  <link
    name="link2">
    <inertial>
      <origin
        xyz="0.1925 5.60895809597873E-16 -1.11022302462516E-16"
        rpy="0 0 0" />
      <mass
        value="2.31769908169873" />
      <inertia
        ixx="0.00233245756808228"
        ixy="2.66184338622923E-17"
        ixz="-1.22851142249759E-17"
        iyy="0.0436330896149885"
        iyz="-1.62130707098142E-19"
        izz="0.042266339997614" />
    </inertial>
    <visual>
      <origin
        xyz="0 0 0"
        rpy="0 0 0" />
      <geometry>
        <mesh
          filename="src/arm_dynamics_hw/urdf/zwzArm/meshes/link2.STL" />
      </geometry>
      <material
        name="">
        <color
          rgba="1 1 1 1" />
      </material>
    </visual>
    <!-- <collision>
      <origin
        xyz="0 0 0"
        rpy="0 0 0" />
      <geometry>
        <mesh
          filename="package://zwzArm/meshes/link2.STL" />
      </geometry>
    </collision> -->
  </link>
  <joint
    name="joint3"
    type="continuous">
    <origin
      xyz="0.385 0 0"
      rpy="0 0 0" />
    <parent
      link="link2" />
    <child
      link="link3" />
    <axis
      xyz="0 -1 0" />
    <limit
      effort="200"
      velocity="30" />
  </joint>
  
  <link
    name="link3">
    <inertial>
      <origin
        xyz="0.179 4.11553069581978E-16 -1.11022302462516E-16"
        rpy="0 0 0" />
      <mass
        value="2.47269908169873" />
      <inertia
        ixx="0.00522228975353902"
        ixy="1.59348073202215E-17"
        ixz="1.66052940727083E-17"
        iyy="0.0369891051288323"
        iyz="2.38592948729878E-19"
        izz="0.0382538543635812" />
    </inertial>
    <visual>
      <origin
        xyz="0 0 0"
        rpy="0 0 0" />
      <geometry>
        <mesh
          filename="src/arm_dynamics_hw/urdf/zwzArm/meshes/link3.STL" />
      </geometry>
      <material
        name="">
        <color
          rgba="1 1 1 1" />
      </material>
    </visual>
    <!-- <collision>
      <origin
        xyz="0 0 0"
        rpy="0 0 0" />
      <geometry>
        <mesh
          filename="package://zwzArm/meshes/link3.STL" />
      </geometry> -->
    <!-- </collision> -->
  </link>
  
      <ros2_control name="GazeboSystem" type="sy.385stem">
        <hardware>
            <plugin>gazebo_ros2_control/GazeboSystem</plugin>
        </hardware>
        <joint name="joint1">
            <command_interface name="position">
                <param name="min">-3.14</param>
                <param name="max">3.14</param>
            </command_interface>
            <command_interface name="velocity">
                <param name="min">-30</param>
                <param name="max">30</param>
            </command_interface>
            <command_interface name="effort">
                <param name="min">-2000</param>
                <param name="max">2000</param>
            </command_interface>
            <state_interface name="position">
                <param name="initial_value">-0.785</param>
            </state_interface>
            <state_interface name="velocity"></state_interface>
            <state_interface name="effort"></state_interface>
        </joint>
        <joint name="joint2">
            <command_interface name="position">
                <param name="min">-3.14</param>
                <param name="max">3.14</param>
            </command_interface>
            <command_interface name="velocity">
                <param name="min">-30</param>
                <param name="max">30</param>
            </command_interface>
            <command_interface name="effort">
                <param name="min">-2000</param>
                <param name="max">2000</param>
            </command_interface>
            <state_interface name="position">
                <param name="initial_value">2.356</param>
            </state_interface>
            <state_interface name="velocity"></state_interface>
            <state_interface name="effort"></state_interface>
        </joint>
        <joint name="joint3">
            <command_interface name="position">
                <param name="min">-3.14</param>
                <param name="max">3.14</param>
            </command_interface>
            <command_interface name="velocity">
                <param name="min">-30</param>
                <param name="max">30</param>
            </command_interface>
            <command_interface name="effort">
                <param name="min">-2000</param>
                <param name="max">2000</param>
            </command_interface>
            <state_interface name="position">
                <param name="initial_value">1.57</param>
            </state_interface>
            <state_interface name="velocity"></state_interface>
            <state_interface name="effort"></state_interface>
        </joint>
    </ros2_control>
    <gazebo>
        <plugin filename="libgazebo_ros2_control.so" name="gazebo_ros2_control">
            <parameters>/home/xsm/R1_ws/src/arm_dynamics_hw/config/effort_control.yaml</parameters>
        </plugin>
    </gazebo>
</robot>