<?xml version="1.0" encoding="utf-8"?>
<!-- This URDF was automatically created by SolidWorks to URDF Exporter! Originally created by Stephen Brawner (brawner@gmail.com) 
     Commit Version: 1.6.0-4-g7f85cfe  Build Version: 1.6.7995.38578
     For more information, please see http://wiki.ros.org/sw_urdf_exporter -->
<robot
  name="ARMvertical">
  <link
    name="base_link">
    <inertial>
      <origin
        xyz="-6.61496605635191E-20 0.25 -5.85635023437615E-19"
        rpy="0 0 0" />
      <mass
        value="2.89269908169872" />
      <inertia
        ixx="0.0816417751742525"
        ixy="-9.59970673554874E-20"
        ixz="1.12937726300573E-20"
        iyy="0.0029314159014156"
        iyz="-5.29395592033938E-20"
        izz="0.083367899791627" />
    </inertial>
    <visual>
      <origin
        xyz="0 0 0"
        rpy="0 0 0" />
      <geometry>
        <mesh
          filename="/home/xsm/R1_ws/src/arm_dynamics_hw/urdf/ARMvertical/meshes/base_link.STL" />
      </geometry>
      <material
        name="">
        <color
          rgba="1 1 1 1" />
      </material>
    </visual>
    <collision>
      <origin
        xyz="0 0 0"
        rpy="0 0 0" />
      <geometry>
        <mesh
          filename="/home/xsm/R1_ws/src/arm_dynamics_hw/urdf/ARMvertical/meshes/base_link.STL" />
      </geometry>
    </collision>
  </link>
  <link
    name="link1">
    <inertial>
      <origin
        xyz="0.16 0 7.8450145613333E-18"
        rpy="0 0 0" />
      <mass
        value="2.09269908169872" />
      <inertia
        ixx="0.00458895642020566"
        ixy="-2.22755641865369E-18"
        ixz="8.98870975313248E-19"
        iyy="0.0295487195783596"
        iyz="-3.12210884956261E-19"
        izz="0.0282839703436107" />
    </inertial>
    <visual>
      <origin
        xyz="0 0 0"
        rpy="0 0 0" />
      <geometry>
        <mesh
          filename="/home/xsm/R1_ws/src/arm_dynamics_hw/urdf/ARMvertical/meshes/link1.STL" />
      </geometry>
      <material
        name="">
        <color
          rgba="1 1 1 1" />
      </material>
    </visual>
    <collision>
      <origin
        xyz="0 0 0"
        rpy="0 0 0" />
      <geometry>
        <mesh
          filename="/home/xsm/R1_ws/src/arm_dynamics_hw/urdf/ARMvertical/meshes/link1.STL" />
      </geometry>
    </collision>
  </link>
  <joint
    name="joint1"
    type="revolute">
    <origin
      xyz="0 0 0.5"
      rpy="-1.5708 0 3.1416" />
    <parent
      link="base_link" />
    <child
      link="link1" />
    <axis
      xyz="0 0 1" />
    <limit
      lower="-3.14"
      upper="3.14"
      effort="23.7"
      velocity="30" />
  </joint>
  <link
    name="link2">
    <inertial>
      <origin
        xyz="0.1925 2.73852122139374E-18 0"
        rpy="0 0 0" />
      <mass
        value="2.31769908169872" />
      <inertia
        ixx="0.00233245756808227"
        ixy="-1.10111797951753E-18"
        ixz="-6.1081025868386E-18"
        iyy="0.0436330896149884"
        iyz="-1.57154690926001E-20"
        izz="0.042266339997614" />
    </inertial>
    <visual>
      <origin
        xyz="0 0 0"
        rpy="0 0 0" />
      <geometry>
        <mesh
          filename="/home/xsm/R1_ws/src/arm_dynamics_hw/urdf/ARMvertical/meshes/link2.STL" />
      </geometry>
      <material
        name="">
        <color
          rgba="1 1 1 1" />
      </material>
    </visual>
    <collision>
      <origin
        xyz="0 0 0"
        rpy="0 0 0" />
      <geometry>
        <mesh
          filename="/home/xsm/R1_ws/src/arm_dynamics_hw/urdf/ARMvertical/meshes/link2.STL" />
      </geometry>
    </collision>
  </link>
  <joint
    name="joint2"
    type="revolute">
    <origin
      xyz="0.32 0 0"
      rpy="-1.5708 0 0" />
    <parent
      link="link1" />
    <child
      link="link2" />
    <axis
      xyz="0 1 0" />
    <limit
      lower="-3.14"
      upper="3.14"
      effort="23.7"
      velocity="30" />
  </joint>
  <link
    name="link3">
    <inertial>
      <origin
        xyz="-0.179 5.55111512312578E-17 -2.9986527615642E-17"
        rpy="0 0 0" />
      <mass
        value="2.47269908169872" />
      <inertia
        ixx="0.00522228975353901"
        ixy="-4.5812344192102E-19"
        ixz="-2.91167575618666E-18"
        iyy="0.0382538543635812"
        iyz="5.09897919989501E-19"
        izz="0.0369891051288322" />
    </inertial>
    <visual>
      <origin
        xyz="0 0 0"
        rpy="0 0 0" />
      <geometry>
        <mesh
          filename="/home/xsm/R1_ws/src/arm_dynamics_hw/urdf/ARMvertical/meshes/link3.STL" />
      </geometry>
      <material
        name="">
        <color
          rgba="1 1 1 1" />
      </material>
    </visual>
    <collision>
      <origin
        xyz="0 0 0"
        rpy="0 0 0" />
      <geometry>
        <mesh
          filename="/home/xsm/R1_ws/src/arm_dynamics_hw/urdf/ARMvertical/meshes/link3.STL" />
      </geometry>
    </collision>
  </link>
  <joint
    name="joint3"
    type="revolute">
    <origin
      xyz="0.385 0 0"
      rpy="-1.5708 0 3.1416" />
    <parent
      link="link2" />
    <child
      link="link3" />
    <axis
      xyz="0 0 1" />
    <limit
      lower="-3.14"
      upper="3.14"
      effort="23.7"
      velocity="30" />
  </joint>
</robot>