<?xml version="1.0" encoding="utf-8"?>
<robot name="R1arm">
    <link name="world" />
    <link name="base_link">
        <inertial>
            <origin xyz="0 0 0.25" rpy="0 0 0"></origin>
            <mass value="2.89269908169872"></mass>
            <inertia ixx="0.0816417751742525" ixy="-9.59970673554874E-20" ixz="1.12937726300573E-20" iyy="0.0029314159014156" iyz="-5.29395592033938E-20" izz="0.083367899791627"></inertia>
        </inertial>
        <visual>
            <origin xyz="0 0 0" rpy="0 0 0"></origin>
            <geometry>
                <mesh filename="/home/xsm/R1_ws/src/arm_dynamics_hw/urdf/meshes/base_link.STL"></mesh>
            </geometry>
            <material name="">
                <color rgba="1 1 1 1"></color>
            </material>
        </visual>
    </link>
    <link name="link1">
        <inertial>
            <origin xyz="-0.16 0 9.36743115896274E-18" rpy="0 0 0"></origin>
            <mass value="2.09269908169872"></mass>
            <inertia ixx="0.00458895642020566" ixy="8.2903203668401E-19" ixz="-8.45931416109854E-19" iyy="0.0295487195783596" iyz="3.12210884956261E-19" izz="0.0282839703436107"></inertia>
        </inertial>
        <visual>
            <origin xyz="0 0 0" rpy="0 0 0"></origin>
            <geometry>
                <mesh filename="/home/xsm/R1_ws/src/arm_dynamics_hw/urdf/meshes/link1.STL"></mesh>
            </geometry>
            <material name="">
                <color rgba="1 1 1 1"></color>
            </material>
        </visual>
    </link>
    <joint name="base_to_world" type="fixed">
            <parent link="world" />
            <child link="base_link" />
            <origin xyz="0 0 0" rpy="1.5708 0 0" />
    </joint>
    <joint name="joint1" type="continuous">
        <origin xyz="0 0.5 0" rpy="0 0 0"></origin>
        <parent link="base_link"></parent>
        <child link="link1"></child>
        <axis xyz="0 0 -1"></axis>
	    <limit effort="20" velocity="30"></limit>
    </joint>
    <link name="link2">
        <inertial>
            <origin xyz="-0.1925 0 -2.90115107698237E-18" rpy="0 0 0"></origin>
            <mass value="2.31769908169872"></mass>
            <inertia ixx="0.00233245756808227" ixy="-6.1081025868386E-18" ixz="-1.10111797951753E-18" iyy="0.042266339997614" iyz="-1.57154690926002E-20" izz="0.0436330896149884"></inertia>
        </inertial>
        <visual>
            <origin xyz="0 0 0" rpy="0 0 0"></origin>
            <geometry>
                <mesh filename="/home/xsm/R1_ws/src/arm_dynamics_hw/urdf/meshes/link2.STL"></mesh>
            </geometry>
            <material name="">
                <color rgba="1 1 1 1"></color>
            </material>
        </visual>

    </link>
    <joint name="joint2" type="continuous">
        <origin xyz="-0.32 0 0" rpy="0 0 0"></origin>
        <parent link="link1"></parent>
        <child link="link2"></child>
        <axis xyz="0 0 -1"></axis>
	    <limit effort="20" velocity="30"></limit>
    </joint>
    <link name="link3">
        <inertial>
            <origin xyz="-0.179 0 -3.08305806577133E-17" rpy="0 0 0"></origin>
            <mass value="2.47269908169872"></mass>
            <inertia ixx="0.00522228975353901" ixy="-4.5812344192102E-19" ixz="-2.86201139104598E-18" iyy="0.0382538543635812" iyz="5.09897919989501E-19" izz="0.0369891051288322"></inertia>
        </inertial>
        <visual>
            <origin xyz="0 0 0" rpy="0 0 0"></origin>
            <geometry>
                <mesh filename="/home/xsm/R1_ws/src/arm_dynamics_hw/urdf/meshes/link3.STL"></mesh>
            </geometry>
            <material name="">
                <color rgba="1 1 1 1"></color>
            </material>
        </visual>

    </link>
    <joint name="joint3" type="continuous">
        <origin xyz="-0.385 0 0" rpy="0 0 0"></origin>
        <parent link="link2"></parent>
        <child link="link3"></child>
        <axis xyz="0 0 -1"></axis>
	    <limit effort="20" velocity="30"></limit>
    </joint>
    <link name="end_ball">
        <inertial>
            <origin xyz="0 0 0" rpy="0 0 0"></origin>
            <mass value="0.0000000000000000000000000000000000001"></mass>
            <inertia ixx="0.0000000000000000000000000000000000001" ixy="0" ixz="0" iyy="0.0000000000000000000000000000000000001" iyz="0" izz="0.0000000000000000000000000000000000001"></inertia>
        </inertial>
        <visual>
            <origin xyz="0 0 0" rpy="0 0 0"></origin>
            <geometry>
                <sphere radius="0.07"></sphere>
            </geometry>
            <material name="red">
                <color rgba="1 0 0 1"></color>
            </material>
        </visual>
    </link>
    <joint name="joint_ball" type="fixed">
        <origin xyz="-0.384 0 0" rpy="0 0 0"></origin>
        <parent link="link3"></parent>
        <child link="end_ball"></child>
    </joint>
    <ros2_control name="GazeboSystem" type="sy.385stem">
        <hardware>
            <plugin>gazebo_ros2_control/GazeboSystem</plugin>
        </hardware>
        <joint name="joint1">
            <command_interface name="position">
                <param name="min">-3.14</param>
                <param name="max">3.14</param>
            </command_interface>
            <command_interface name="velocity">
                <param name="min">-30</param>
                <param name="max">30</param>
            </command_interface>
            <command_interface name="effort">
                <param name="min">-20</param>
                <param name="max">20</param>
            </command_interface>
            <state_interface name="position">
                <param name="initial_value">-0.785</param>
            </state_interface>
            <state_interface name="velocity"></state_interface>
            <state_interface name="effort"></state_interface>
        </joint>
        <joint name="joint2">
            <command_interface name="position">
                <param name="min">-3.14</param>
                <param name="max">3.14</param>
            </command_interface>
            <command_interface name="velocity">
                <param name="min">-30</param>
                <param name="max">30</param>
            </command_interface>
            <command_interface name="effort">
                <param name="min">-20</param>
                <param name="max">20</param>
            </command_interface>
            <state_interface name="position">
                <param name="initial_value">2.356</param>
            </state_interface>
            <state_interface name="velocity"></state_interface>
            <state_interface name="effort"></state_interface>
        </joint>
        <joint name="joint3">
            <command_interface name="position">
                <param name="min">-3.14</param>
                <param name="max">3.14</param>
            </command_interface>
            <command_interface name="velocity">
                <param name="min">-30</param>
                <param name="max">30</param>
            </command_interface>
            <command_interface name="effort">
                <param name="min">-20</param>
                <param name="max">20</param>
            </command_interface>
            <state_interface name="position">
                <param name="initial_value">1.57</param>
            </state_interface>
            <state_interface name="velocity"></state_interface>
            <state_interface name="effort"></state_interface>
        </joint>
    </ros2_control>
    <gazebo>
        <plugin filename="libgazebo_ros2_control.so" name="gazebo_ros2_control">
            <parameters>/home/xsm/R1_ws/src/arm_dynamics_hw/config/effort_control.yaml</parameters>
        </plugin>
    </gazebo>
</robot>
