<?xml version="1.0" encoding="utf-8"?>
<!-- This URDF was automatically created by SolidWorks to URDF Exporter! Originally created by Stephen Brawner (brawner@gmail.com) 
     Commit Version: 1.6.0-4-g7f85cfe  Build Version: 1.6.7995.38578
     For more information, please see http://wiki.ros.org/sw_urdf_exporter -->
<robot
  name="R1ARMvertical">
  <link
    name="base_link">
    <inertial>
      <origin
        xyz="-1.17127004687523E-19 5.85635023437615E-19 0.25"
        rpy="0 0 0" />
      <mass
        value="2.89269908169873" />
      <inertia
        ixx="0.0816417751742525"
        ixy="-1.12937726300573E-20"
        ixz="-9.59970673554874E-20"
        iyy="0.083367899791627"
        iyz="5.29395592033938E-20"
        izz="0.0029314159014156" />
    </inertial>
    <visual>
      <origin
        xyz="0 0 0"
        rpy="0 0 0" />
      <geometry>
        <mesh
          filename="package://R1ARMvertical/meshes/base_link.STL" />
      </geometry>
      <material
        name="">
        <color
          rgba="1 1 1 1" />
      </material>
    </visual>
    <collision>
      <origin
        xyz="0 0 0"
        rpy="0 0 0" />
      <geometry>
        <mesh
          filename="package://R1ARMvertical/meshes/base_link.STL" />
      </geometry>
    </collision>
  </link>
  <link
    name="link1">
    <inertial>
      <origin
        xyz="-0.159999999999991 -1.14866254970031E-17 -1.48769885299771E-14"
        rpy="0 0 0" />
      <mass
        value="2.09269908169872" />
      <inertia
        ixx="0.00458895642020566"
        ixy="8.45562983043023E-19"
        ixz="8.2903203668401E-19"
        iyy="0.0282839703436107"
        iyz="-3.12210884956261E-19"
        izz="0.0295487195783596" />
    </inertial>
    <visual>
      <origin
        xyz="0 0 0"
        rpy="0 0 0" />
      <geometry>
        <mesh
          filename="package://R1ARMvertical/meshes/link1.STL" />
      </geometry>
      <material
        name="">
        <color
          rgba="1 1 1 1" />
      </material>
    </visual>
    <collision>
      <origin
        xyz="0 0 0"
        rpy="0 0 0" />
      <geometry>
        <mesh
          filename="package://R1ARMvertical/meshes/link1.STL" />
      </geometry>
    </collision>
  </link>
  <joint
    name="joint1"
    type="revolute">
    <origin
      xyz="0 0 0.5"
      rpy="0 0 0" />
    <parent
      link="base_link" />
    <child
      link="link1" />
    <axis
      xyz="0 -1 0" />
    <limit
      lower="-3.14"
      upper="3.14"
      effort="23.7"
      velocity="30" />
  </joint>
  <link
    name="link2">
    <inertial>
      <origin
        xyz="-0.1925 2.7385E-18 0"
        rpy="0 0 0" />
      <mass
        value="2.3177" />
      <inertia
        ixx="0.0023325"
        ixy="1.1011E-18"
        ixz="-6.1081E-18"
        iyy="0.043633"
        iyz="1.5715E-20"
        izz="0.042266" />
    </inertial>
    <visual>
      <origin
        xyz="0 0 0"
        rpy="0 0 0" />
      <geometry>
        <mesh
          filename="package://R1ARMvertical/meshes/link2.STL" />
      </geometry>
      <material
        name="">
        <color
          rgba="1 1 1 1" />
      </material>
    </visual>
    <collision>
      <origin
        xyz="0 0 0"
        rpy="0 0 0" />
      <geometry>
        <mesh
          filename="package://R1ARMvertical/meshes/link2.STL" />
      </geometry>
    </collision>
  </link>
  <joint
    name="joint2"
    type="revolute">
    <origin
      xyz="-0.32 0 0"
      rpy="0 0 0" />
    <parent
      link="link1" />
    <child
      link="link2" />
    <axis
      xyz="0 -1 0" />
    <limit
      lower="-3.14"
      upper="3.14"
      effort="23.7"
      velocity="30" />
  </joint>
  <link
    name="link3">
    <inertial>
      <origin
        xyz="-0.179 2.96439736212949E-17 0"
        rpy="0 0 0" />
      <mass
        value="2.47269908169872" />
      <inertia
        ixx="0.00522228975353901"
        ixy="2.91167575618666E-18"
        ixz="-4.5812344192102E-19"
        iyy="0.0369891051288322"
        iyz="-5.09897919989501E-19"
        izz="0.0382538543635812" />
    </inertial>
    <visual>
      <origin
        xyz="0 0 0"
        rpy="0 0 0" />
      <geometry>
        <mesh
          filename="package://R1ARMvertical/meshes/link3.STL" />
      </geometry>
      <material
        name="">
        <color
          rgba="1 1 1 1" />
      </material>
    </visual>
    <collision>
      <origin
        xyz="0 0 0"
        rpy="0 0 0" />
      <geometry>
        <mesh
          filename="package://R1ARMvertical/meshes/link3.STL" />
      </geometry>
    </collision>
  </link>
  <joint
    name="joint3"
    type="continuous">
    <origin
      xyz="-0.385 0 0"
      rpy="0 0 0" />
    <parent
      link="link2" />
    <child
      link="link3" />
    <axis
      xyz="0 -1 0" />
    <limit
      lower="-3.14"
      upper="3.14"
      effort="23.7"
      velocity="30" />
  </joint>
</robot>