<?xml version="1.0" encoding="utf-8"?>
<!-- This URDF was automatically created by SolidWorks to URDF Exporter! Originally created by Stephen Brawner (brawner@gmail.com) 
     Commit Version: 1.6.0-4-g7f85cfe  Build Version: 1.6.7995.38578
     For more information, please see http://wiki.ros.org/sw_urdf_exporter -->
<robot
  name="FinalARM">
  <link name="world" />
    <joint name="base_to_world" type="fixed">
              <parent link="world" />
              <child link="base_link" />
              <origin xyz="0 0 1" rpy="0 0 0" />
    </joint>
  <link
    name="base_link">
    <inertial>
      <origin
        xyz="2.84868459203974E-05 0.00646103306923534 0.051690961201876"
        rpy="0 0 0" />
      <mass
        value="0.638560833290428" />
      <inertia
        ixx="0.000342424803096954"
        ixy="3.06353508396627E-08"
        ixz="-3.8429357482614E-07"
        iyy="0.000952347722591278"
        iyz="-1.3985079663822E-06"
        izz="0.000643762246471619" />
    </inertial>
    <visual>
      <origin
        xyz="0 0 0"
        rpy="0 0 0" />
      <geometry>
        <mesh
          filename="src/arm_dynamics_hw/urdf/FinalARM/meshes/base_link.STL" />
      </geometry>
      <material
        name="">
        <color
          rgba="0.792156862745098 0.819607843137255 0.933333333333333 1" />
      </material>
    </visual>
    <!-- <collision>
      <origin
        xyz="0 0 0"
        rpy="0 0 0" />
      <geometry>
        <mesh
          filename="src/arm_dynamics_hw/urdf/FinalARM/meshes/base_link.STL" />
      </geometry>
    </collision> -->
  </link>
  <link
    name="link1">
    <inertial>
      <origin
        xyz="0.40022 0.01589 0.06996"
        rpy="0 0 0" />
      <mass
        value="1.2" />
      <inertia
        ixx="0.002272764"
        ixy="0.002592921"
        ixz="-0.000006758"
        iyy="0.026805022"
        iyz="-0.000001987"
        izz="0.028075661" />
    </inertial>
    <visual>
      <origin
        xyz="0 0 0"
        rpy="0 0 0" />
      <geometry>
        <mesh
          filename="src/arm_dynamics_hw/urdf/FinalARM/meshes/link1.STL" />
      </geometry>
      <material
        name="">
        <color
          rgba="0.752941176470588 0.752941176470588 0.752941176470588 1" />
      </material>
    </visual>
    <!-- <collision>
      <origin
        xyz="0 0 0"
        rpy="0 0 0" />
      <geometry>
        <mesh
          filename="src/arm_dynamics_hw/urdf/FinalARM/meshes/link1.STL" />
      </geometry>
    </collision> -->
  </link>
  <joint
    name="joint1"
    type="continuous">
    <origin
      xyz="0 0 0.07"
      rpy="0 0 0" />
    <parent
      link="base_link" />
    <child
      link="link1" />
    <axis
      xyz="0 -1 0" />
    <limit
      effort="20"
      velocity="30" />
  </joint>
  <link
    name="link2">
    <inertial>
      <origin
        xyz="0.40134 -0.00435 0.06994"
        rpy="0 0 0" />
      <mass
        value="0.8" />
      <inertia
        ixx="0.000526181"
        ixy="-0.000164053"
        ixz="-0.000005374"
        iyy="0.023046232"
        iyz="-0.000000526"
        izz="0.022789133" />
    </inertial>
    <visual>
      <origin
        xyz="0 0 0"
        rpy="0 0 0" />
      <geometry>
        <mesh
          filename="src/arm_dynamics_hw/urdf/FinalARM/meshes/link2.STL" />
      </geometry>
      <material
        name="">
        <color
          rgba="0.752941176470588 0.752941176470588 0.752941176470588 1" />
      </material>
    </visual>
    <!-- <collision>
      <origin
        xyz="0 0 0"
        rpy="0 0 0" />
      <geometry>
        <mesh
          filename="src/arm_dynamics_hw/urdf/FinalARM/meshes/link2.STL" />
      </geometry>
    </collision> -->
  </link>
  <joint
    name="joint2"
    type="continuous">
    <origin
      xyz="0.42 0 0"
      rpy="0 0 0" />
    <parent
      link="link1" />
    <child
      link="link2" />
    <axis
      xyz="0 -1 0" />
    <limit
      effort="20"
      velocity="30" />
  </joint>
  <link
    name="link3">
    <inertial>
      <origin
        xyz="0.149 -0.00279 0.08695"
        rpy="0 0 0" />
      <mass
        value="0.75" />
      <inertia
        ixx="0.001947338"
        ixy="0.000037439"
        ixz="0.000559185"
        iyy="0.007281292"
        iyz="-0.000076356"
        izz="0.007065304" />
    </inertial>
    <visual>
      <origin
        xyz="0 0 0"
        rpy="0 0 0" />
      <geometry>
        <mesh
          filename="src/arm_dynamics_hw/urdf/FinalARM/meshes/link3.STL" />
      </geometry>
      <material
        name="">
        <color
          rgba="0.752941176470588 0.752941176470588 0.752941176470588 1" />
      </material>
    </visual>
    <!-- <collision>
      <origin
        xyz="0 0 0"
        rpy="0 0 0" />
      <geometry>
        <mesh
          filename="src/arm_dynamics_hw/urdf/FinalARM/meshes/link3.STL" />
      </geometry>
    </collision> -->
  </link>
  <joint
    name="joint3"
    type="continuous">
    <origin
      xyz="0.48307 0 0"
      rpy="0 0 0" />
    <parent
      link="link2" />
    <child
      link="link3" />
    <axis
      xyz="0 -1 0" />
    <limit
      effort="20"
      velocity="30" />
  </joint>

  <ros2_control name="GazeboSystem" type="sy.385stem">
        <hardware>
            <plugin>gazebo_ros2_control/GazeboSystem</plugin>
        </hardware>
        <joint name="joint1">
            <command_interface name="position">
                <param name="min">-3.14</param>
                <param name="max">3.14</param>
            </command_interface>
            <command_interface name="velocity">
                <param name="min">-30</param>
                <param name="max">30</param>
            </command_interface>
            <command_interface name="effort">
                <param name="min">-20</param>
                <param name="max">20</param>
            </command_interface>
            <state_interface name="position">
                <param name="initial_value">-0.785</param>
            </state_interface>
            <state_interface name="velocity"></state_interface>
            <state_interface name="effort"></state_interface>
        </joint>
        <joint name="joint2">
            <command_interface name="position">
                <param name="min">-3.14</param>
                <param name="max">3.14</param>
            </command_interface>
            <command_interface name="velocity">
                <param name="min">-30</param>
                <param name="max">30</param>
            </command_interface>
            <command_interface name="effort">
                <param name="min">-20</param>
                <param name="max">20</param>
            </command_interface>
            <state_interface name="position">
                <param name="initial_value">2.356</param>
            </state_interface>
            <state_interface name="velocity"></state_interface>
            <state_interface name="effort"></state_interface>
        </joint>
        <joint name="joint3">
            <command_interface name="position">
                <param name="min">-3.14</param>
                <param name="max">3.14</param>
            </command_interface>
            <command_interface name="velocity">
                <param name="min">-30</param>
                <param name="max">30</param>
            </command_interface>
            <command_interface name="effort">
                <param name="min">-20</param>
                <param name="max">20</param>
            </command_interface>
            <state_interface name="position">
                <param name="initial_value">1.5707</param>
            </state_interface>
            <state_interface name="velocity"></state_interface>
            <state_interface name="effort"></state_interface>
        </joint>
    </ros2_control>
    <gazebo>
        <plugin filename="libgazebo_ros2_control.so" name="gazebo_ros2_control">
            <parameters>/home/xsm/R1_ws/src/arm_dynamics_hw/config/effort_control.yaml</parameters>
        </plugin>
    </gazebo>
</robot>